Workbook

Sheet FREIGHT
A2: BILL NO | B2: BILL DATE | C2: SR NO | D2: DATE | E2: VH NO | F2: DRIVER | G2: BILLING PARTY | H2: ADDRESS | I2: FROM PARTY NAME | J2: FROM PLACE | K2: TO PARTY NAME | L2: TO PLACE | M2: DISTANCE (IN KM) | N2: CS LR NO | O2: PARTY BILL NO | P2: WEIGHT | Q2: BASIC FREIGHT | R2: ACTUAL FREIGHT | S2: DETAINTION | T2: TOTAL AMOUNT | U2: DETAINTION DETAILS | V2: DIESEL | W2: TOLL | X2: DRIVER EXP | Y2: OTHER EXP | Z2: FIXED EXP | AA2: TOTAL COST | AB2: GROSS PL
A3: 1 | B3: 46113 | C3: =SUBTOTAL(3,D$3:D3) -> 1 | D3: 46113 | E3: MH12NX9008 | F3: VIJAY | G3: SBD CHK | H3: =+VLOOKUP(Table1[[#This Row],[BILLING PARTY]],'PARTY CREATION'!$B:$I,2,) -> CHAKAN | I3: MTC CHAKAN | J3: CHK | K3: KFIL | L3: JEJURI | M3: 200 | N3: 100 | O3: 10 | P3: 25 | Q3: 6500 | R3: =+ROUND(IF(P3>10,Q3/10*P3,Q3),0) -> 16250 | S3: 4000 | T3: =+R3+S3 -> 20250 | V3: 7000 | W3: 1100 | X3: 700 | Y3: 500 | Z3: 200 | AA3: =+SUM(Table1[[#This Row],[DIESEL]:[FIXED EXP]]) -> 9500 | AB3: =+Table1[[#This Row],[TOTAL AMOUNT]]-Table1[[#This Row],[TOTAL COST]] -> 10750
A4: 1 | B4: 46114 | C4: =SUBTOTAL(3,D$3:D4) -> 2 | D4: 46114 | E4: MH14KA2022 | F4: VIJAY | G4: MTSPL TAL | H4: CHAKAN | I4: MTC TALAWADE | J4: TAL | K4: KFIL | L4: JEJURI | M4: 200 | N4: 101 | O4: 20 | P4: 25 | Q4: 6500 | R4: =+ROUND(IF(P4>10,Q4/10*P4,Q4),0) -> 16250 | S4: 2000 | T4: =+R4+S4 -> 18250 | AA4: =+SUM(Table1[[#This Row],[DIESEL]:[FIXED EXP]]) -> 0 | AB4: =+Table1[[#This Row],[TOTAL AMOUNT]]-Table1[[#This Row],[TOTAL COST]] -> 18250
A5: 1 | B5: 46115 | C5: =SUBTOTAL(3,D$3:D5) -> 3 | D5: 46115 | E5: MH12LT4896 | F5: RAHUL MANE | G5: MTSPL TAL | H5: CHAKAN | I5: MTC TALAWADE | J5: TAL | K5: KFIL | L5: JEJURI | M5: 200 | N5: 102 | O5: 30 | P5: 25 | Q5: 6500 | R5: =+ROUND(IF(P5>10,Q5/10*P5,Q5),0) -> 16250 | S5: 1000 | T5: =+R5+S5 -> 17250 | AA5: =+SUM(Table1[[#This Row],[DIESEL]:[FIXED EXP]]) -> 0 | AB5: =+Table1[[#This Row],[TOTAL AMOUNT]]-Table1[[#This Row],[TOTAL COST]] -> 17250
A6: 1 | B6: 46116 | C6: =SUBTOTAL(3,D$3:D6) -> 4 | D6: 46116 | E6: MH12KP5927 | F6: ASHOK DRVER | G6: MTSPL TAL | H6: CHAKAN | I6: MTC TALAWADE | J6: TAL | K6: KFIL | L6: JEJURI | M6: 200 | N6: 103 | O6: 40 | P6: 25 | Q6: 7000 | R6: =+ROUND(IF(P6>10,Q6/10*P6,Q6),0) -> 17500 | T6: =+R6+S6 -> 17500 | AA6: =+SUM(Table1[[#This Row],[DIESEL]:[FIXED EXP]]) -> 0 | AB6: =+Table1[[#This Row],[TOTAL AMOUNT]]-Table1[[#This Row],[TOTAL COST]] -> 17500
A7: 1 | B7: 46117 | C7: =SUBTOTAL(3,D$3:D7) -> 5 | D7: 46117 | E7: MH12LT5574 | F7: GOKUL | G7: MTSPL TAL | H7: CHAKAN | I7: MTC TALAWADE | J7: CHK | K7: KFIL | L7: JEJURI | M7: 200 | N7: 104 | O7: 50 | P7: 25 | Q7: 7000 | R7: =+ROUND(IF(P7>10,Q7/10*P7,Q7),0) -> 17500 | T7: =+R7+S7 -> 17500 | AA7: =+SUM(Table1[[#This Row],[DIESEL]:[FIXED EXP]]) -> 0 | AB7: =+Table1[[#This Row],[TOTAL AMOUNT]]-Table1[[#This Row],[TOTAL COST]] -> 17500
A8: 2 | B8: 46118 | C8: =SUBTOTAL(3,D$3:D8) -> 6 | D8: 46118 | E8: MH14NE5834 | F8: KISAN KURKUTE | G8: MTSPL TAL | H8: CHAKAN | I8: MTC TALAWADE | J8: CHK | K8: MTC CHK | O8: 60 | P8: 25 | Q8: 6500 | R8: =+ROUND(IF(P8>10,Q8/10*P8,Q8),0) -> 16250 | T8: =+R8+S8 -> 16250 | AA8: =+SUM(Table1[[#This Row],[DIESEL]:[FIXED EXP]]) -> 0 | AB8: =+Table1[[#This Row],[TOTAL AMOUNT]]-Table1[[#This Row],[TOTAL COST]] -> 16250
A9: 2 | B9: 46119 | C9: =SUBTOTAL(3,D$3:D9) -> 7 | D9: 46119 | E9: MH14BJ6005 | F9: RANJEET | G9: MTSPL CHK | H9: CHAKAN | I9: MTC CHAKAN | K9: MTC CHK | O9: 70 | P9: 25 | Q9: 6500 | R9: =+ROUND(IF(P9>10,Q9/10*P9,Q9),0) -> 16250 | T9: =+R9+S9 -> 16250 | AA9: =+SUM(Table1[[#This Row],[DIESEL]:[FIXED EXP]]) -> 0 | AB9: =+Table1[[#This Row],[TOTAL AMOUNT]]-Table1[[#This Row],[TOTAL COST]] -> 16250
A10: 2 | B10: 46120 | C10: =SUBTOTAL(3,D$3:D10) -> 8 | D10: 46120 | E10: MH14HG8875 | F10: RAJESH KUSALKAR | H10: CHAKAN | I10: MTC TALAWADE | K10: MTC CHK | O10: 80 | P10: 25 | Q10: 6500 | R10: =+ROUND(IF(P10>10,Q10/10*P10,Q10),0) -> 16250 | T10: =+R10+S10 -> 16250 | AA10: =+SUM(Table1[[#This Row],[DIESEL]:[FIXED EXP]]) -> 0 | AB10: =+Table1[[#This Row],[TOTAL AMOUNT]]-Table1[[#This Row],[TOTAL COST]] -> 16250
A11: 2 | B11: 46121 | C11: =SUBTOTAL(3,D$3:D11) -> 9 | D11: 46121 | E11: MH14HG5589 | F11: RAJESH KUSALKAR | H11: CHAKAN | I11: MTC TALAWADE | K11: MTC CHK | O11: 90 | P11: 25 | Q11: 6500 | R11: =+ROUND(IF(P11>10,Q11/10*P11,Q11),0) -> 16250 | T11: =+R11+S11 -> 16250 | AA11: =+SUM(Table1[[#This Row],[DIESEL]:[FIXED EXP]]) -> 0 | AB11: =+Table1[[#This Row],[TOTAL AMOUNT]]-Table1[[#This Row],[TOTAL COST]] -> 16250
A12: 2 | B12: 46122 | C12: =SUBTOTAL(3,D$3:D12) -> 10 | D12: 46122 | H12: CHAKAN | I12: MTC TALAWADE | K12: MTC CHK | O12: 100 | P12: 25 | Q12: 2400 | R12: =+ROUND(IF(P12>10,Q12/10*P12,Q12),0) -> 6000 | T12: =+R12+S12 -> 6000 | AA12: =+SUM(Table1[[#This Row],[DIESEL]:[FIXED EXP]]) -> 0 | AB12: =+Table1[[#This Row],[TOTAL AMOUNT]]-Table1[[#This Row],[TOTAL COST]] -> 6000
A13: 11 | B13: 46123 | C13: =SUBTOTAL(3,D$3:D13) -> 11 | D13: 46123 | H13: CHAKAN | I13: MTC TALAWADE | O13: 110 | P13: 5 | Q13: 2400 | R13: =+ROUND(IF(P13>10,Q13/10*P13,Q13),0) -> 2400 | T13: =+R13+S13 -> 2400 | AA13: =+SUM(Table1[[#This Row],[DIESEL]:[FIXED EXP]]) -> 0 | AB13: =+Table1[[#This Row],[TOTAL AMOUNT]]-Table1[[#This Row],[TOTAL COST]] -> 2400
A14: 12 | B14: 46124 | C14: =SUBTOTAL(3,D$3:D14) -> 12 | D14: 46124 | H14: CHAKAN | I14: MTC TALAWADE | O14: 120 | P14: 4.28 | Q14: 2400 | R14: =+ROUND(IF(P14>10,Q14/10*P14,Q14),0) -> 2400 | T14: =+R14+S14 -> 2400 | AA14: =+SUM(Table1[[#This Row],[DIESEL]:[FIXED EXP]]) -> 0 | AB14: =+Table1[[#This Row],[TOTAL AMOUNT]]-Table1[[#This Row],[TOTAL COST]] -> 2400
A15: 13 | B15: 46125 | C15: =SUBTOTAL(3,D$3:D15) -> 13 | D15: 46125 | H15: CHAKAN | I15: MTC CHAKAN | O15: 130 | P15: 8.82 | Q15: 2400 | R15: =+ROUND(IF(P15>10,Q15/10*P15,Q15),0) -> 2400 | T15: =+R15+S15 -> 2400 | AA15: =+SUM(Table1[[#This Row],[DIESEL]:[FIXED EXP]]) -> 0 | AB15: =+Table1[[#This Row],[TOTAL AMOUNT]]-Table1[[#This Row],[TOTAL COST]] -> 2400
A16: 14 | B16: 46126 | C16: =SUBTOTAL(3,D$3:D16) -> 14 | D16: 46126 | H16: CHAKAN | I16: MTC TALAWADE | O16: 140 | P16: 3.65 | Q16: 2400 | R16: =+ROUND(IF(P16>10,Q16/10*P16,Q16),0) -> 2400 | T16: =+R16+S16 -> 2400 | AA16: =+SUM(Table1[[#This Row],[DIESEL]:[FIXED EXP]]) -> 0 | AB16: =+Table1[[#This Row],[TOTAL AMOUNT]]-Table1[[#This Row],[TOTAL COST]] -> 2400
A17: 15 | B17: 46127 | C17: =SUBTOTAL(3,D$3:D17) -> 15 | D17: 46127 | H17: CHAKAN | I17: MTC TALAWADE | O17: 150 | P17: 4.51 | Q17: 2400 | R17: =+ROUND(IF(P17>10,Q17/10*P17,Q17),0) -> 2400 | T17: =+R17+S17 -> 2400 | AA17: =+SUM(Table1[[#This Row],[DIESEL]:[FIXED EXP]]) -> 0 | AB17: =+Table1[[#This Row],[TOTAL AMOUNT]]-Table1[[#This Row],[TOTAL COST]] -> 2400
A18: 16 | B18: 46128 | C18: =SUBTOTAL(3,D$3:D18) -> 16 | D18: 46128 | H18: CHAKAN | I18: MTC TALAWADE | O18: 160 | P18: 4.23 | Q18: 2400 | R18: =+ROUND(IF(P18>10,Q18/10*P18,Q18),0) -> 2400 | T18: =+R18+S18 -> 2400 | AA18: =+SUM(Table1[[#This Row],[DIESEL]:[FIXED EXP]]) -> 0 | AB18: =+Table1[[#This Row],[TOTAL AMOUNT]]-Table1[[#This Row],[TOTAL COST]] -> 2400
A19: 17 | B19: 46129 | C19: =SUBTOTAL(3,D$3:D19) -> 17 | D19: 46129 | H19: CHAKAN | I19: MTC TALAWADE | O19: 170 | P19: 4.03 | Q19: 2400 | R19: =+ROUND(IF(P19>10,Q19/10*P19,Q19),0) -> 2400 | T19: =+R19+S19 -> 2400 | AA19: =+SUM(Table1[[#This Row],[DIESEL]:[FIXED EXP]]) -> 0 | AB19: =+Table1[[#This Row],[TOTAL AMOUNT]]-Table1[[#This Row],[TOTAL COST]] -> 2400
A20: 18 | B20: 46130 | C20: =SUBTOTAL(3,D$3:D20) -> 18 | D20: 46130 | H20: CHAKAN | I20: MTC TALAWADE | O20: 180 | P20: 4.36 | Q20: 2400 | R20: =+ROUND(IF(P20>10,Q20/10*P20,Q20),0) -> 2400 | T20: =+R20+S20 -> 2400 | AA20: =+SUM(Table1[[#This Row],[DIESEL]:[FIXED EXP]]) -> 0 | AB20: =+Table1[[#This Row],[TOTAL AMOUNT]]-Table1[[#This Row],[TOTAL COST]] -> 2400
A21: 19 | B21: 46131 | C21: =SUBTOTAL(3,D$3:D21) -> 19 | D21: 46131 | H21: CHAKAN | I21: MTC TALAWADE | O21: 190 | P21: 4.42 | Q21: 2400 | R21: =+ROUND(IF(P21>10,Q21/10*P21,Q21),0) -> 2400 | T21: =+R21+S21 -> 2400 | AA21: =+SUM(Table1[[#This Row],[DIESEL]:[FIXED EXP]]) -> 0 | AB21: =+Table1[[#This Row],[TOTAL AMOUNT]]-Table1[[#This Row],[TOTAL COST]] -> 2400
A22: 20 | B22: 46132 | C22: =SUBTOTAL(3,D$3:D22) -> 20 | D22: 46132 | H22: CHAKAN | I22: MTC TALAWADE | O22: 200 | P22: 4.5 | Q22: 2400 | R22: =+ROUND(IF(P22>10,Q22/10*P22,Q22),0) -> 2400 | T22: =+R22+S22 -> 2400 | AA22: =+SUM(Table1[[#This Row],[DIESEL]:[FIXED EXP]]) -> 0 | AB22: =+Table1[[#This Row],[TOTAL AMOUNT]]-Table1[[#This Row],[TOTAL COST]] -> 2400
A23: 21 | B23: 46133 | C23: =SUBTOTAL(3,D$3:D23) -> 21 | D23: 46133 | H23: CHAKAN | I23: MTC TALAWADE | O23: 210 | P23: 4.36 | Q23: 2400 | R23: =+ROUND(IF(P23>10,Q23/10*P23,Q23),0) -> 2400 | T23: =+R23+S23 -> 2400 | AA23: =+SUM(Table1[[#This Row],[DIESEL]:[FIXED EXP]]) -> 0 | AB23: =+Table1[[#This Row],[TOTAL AMOUNT]]-Table1[[#This Row],[TOTAL COST]] -> 2400
A24: 22 | B24: 46134 | C24: =SUBTOTAL(3,D$3:D24) -> 22 | D24: 46134 | H24: CHAKAN | I24: MTC TALAWADE | O24: 220 | P24: 3.82 | Q24: 2400 | R24: =+ROUND(IF(P24>10,Q24/10*P24,Q24),0) -> 2400 | T24: =+R24+S24 -> 2400 | AA24: =+SUM(Table1[[#This Row],[DIESEL]:[FIXED EXP]]) -> 0 | AB24: =+Table1[[#This Row],[TOTAL AMOUNT]]-Table1[[#This Row],[TOTAL COST]] -> 2400
... A48: 46 | B48: 46158 | C48: =SUBTOTAL(3,D$3:D48) -> 46 | D48: 46158 | H48: CHAKAN | I48: MTC TALAWADE | O48: 460 | P48: 5.03 | Q48: 2400 | R48: =+ROUND(IF(P48>10,Q48/10*P48,Q48),0) -> 2400 | T48: =+R48+S48 -> 2400 | AA48: =+SUM(Table1[[#This Row],[DIESEL]:[FIXED EXP]]) -> 0 | AB48: =+Table1[[#This Row],[TOTAL AMOUNT]]-Table1[[#This Row],[TOTAL COST]] -> 2400
A49: 47 | B49: 46159 | C49: =SUBTOTAL(3,D$3:D48) -> 46 | D49: 46159 | H49: CHAKAN | I49: MTC TALAWADE | O49: 470 | P49: 4.39 | Q49: 2400 | R49: =+ROUND(IF(P48>10,Q48/10*P48,Q48),0) -> 2400 | T49: =+R48+S48 -> 2400 | AA49: =+SUM(Table1[[#This Row],[DIESEL]:[FIXED EXP]]) -> 0 | AB49: =+Table1[[#This Row],[TOTAL AMOUNT]]-Table1[[#This Row],[TOTAL COST]] -> 2400
A50: 48 | B50: 46160 | C50: =SUBTOTAL(3,D$3:D50) -> 48 | D50: 46160 | H50: CHAKAN | I50: MTC TALAWADE | O50: 480 | P50: 4.57 | Q50: 3200 | R50: =+ROUND(IF(P50>10,Q50/10*P50,Q50),0) -> 3200 | T50: =+R50+S50 -> 3200 | AA50: =+SUM(Table1[[#This Row],[DIESEL]:[FIXED EXP]]) -> 0 | AB50: =+Table1[[#This Row],[TOTAL AMOUNT]]-Table1[[#This Row],[TOTAL COST]] -> 3200
A51: 49 | B51: 46161 | C51: =SUBTOTAL(3,D$3:D51) -> 49 | D51: 46161 | H51: CHAKAN | I51: MTC TALAWADE | O51: 490 | P51: 4.57 | Q51: 2400 | R51: =+ROUND(IF(P51>10,Q51/10*P51,Q51),0) -> 2400 | T51: =+R51+S51 -> 2400 | AA51: =+SUM(Table1[[#This Row],[DIESEL]:[FIXED EXP]]) -> 0 | AB51: =+Table1[[#This Row],[TOTAL AMOUNT]]-Table1[[#This Row],[TOTAL COST]] -> 2400
A52: 50 | B52: 46162 | C52: =SUBTOTAL(3,D$3:D52) -> 50 | D52: 46162 | H52: CHAKAN | I52: MTC TALAWADE | O52: 500 | P52: 4.77 | Q52: 2400 | R52: =+ROUND(IF(P52>10,Q52/10*P52,Q52),0) -> 2400 | T52: =+R52+S52 -> 2400 | AA52: =+SUM(Table1[[#This Row],[DIESEL]:[FIXED EXP]]) -> 0 | AB52: =+Table1[[#This Row],[TOTAL AMOUNT]]-Table1[[#This Row],[TOTAL COST]] -> 2400
A53: 51 | B53: 46163 | C53: =SUBTOTAL(3,D$3:D53) -> 51 | D53: 46163 | H53: CHAKAN | I53: MTC CHAKAN | O53: 510 | P53: 5.735 | Q53: 2350 | R53: =+ROUND(IF(P53>10,Q53/10*P53,Q53),0) -> 2350 | T53: =+R53+S53 -> 2350 | AA53: =+SUM(Table1[[#This Row],[DIESEL]:[FIXED EXP]]) -> 0 | AB53: =+Table1[[#This Row],[TOTAL AMOUNT]]-Table1[[#This Row],[TOTAL COST]] -> 2350
A54: 52 | B54: 46164 | C54: =SUBTOTAL(3,D$3:D54) -> 52 | D54: 46164 | H54: CHAKAN | I54: MTC TALAWADE | O54: 520 | P54: 4.88 | Q54: 3200 | R54: =+ROUND(IF(P54>10,Q54/10*P54,Q54),0) -> 3200 | T54: =+R54+S54 -> 3200 | AA54: =+SUM(Table1[[#This Row],[DIESEL]:[FIXED EXP]]) -> 0 | AB54: =+Table1[[#This Row],[TOTAL AMOUNT]]-Table1[[#This Row],[TOTAL COST]] -> 3200
A55: 53 | B55: 46165 | C55: =SUBTOTAL(3,D$3:D55) -> 53 | D55: 46165 | H55: CHAKAN | I55: MTC TALAWADE | O55: 530 | P55: 4.87 | Q55: 3200 | R55: =+ROUND(IF(P55>10,Q55/10*P55,Q55),0) -> 3200 | T55: =+R55+S55 -> 3200 | AA55: =+SUM(Table1[[#This Row],[DIESEL]:[FIXED EXP]]) -> 0 | AB55: =+Table1[[#This Row],[TOTAL AMOUNT]]-Table1[[#This Row],[TOTAL COST]] -> 3200
A56: 54 | B56: 46166 | C56: =SUBTOTAL(3,D$3:D56) -> 54 | D56: 46166 | H56: CHAKAN | I56: MTC CHAKAN | O56: 540 | P56: 6.76 | Q56: 2350 | R56: =+ROUND(IF(P56>10,Q56/10*P56,Q56),0) -> 2350 | T56: =+R56+S56 -> 2350 | AA56: =+SUM(Table1[[#This Row],[DIESEL]:[FIXED EXP]]) -> 0 | AB56: =+Table1[[#This Row],[TOTAL AMOUNT]]-Table1[[#This Row],[TOTAL COST]] -> 2350
A57: 55 | B57: 46167 | C57: =SUBTOTAL(3,D$3:D57) -> 55 | D57: 46167 | H57: CHAKAN | I57: MTC TALAWADE | O57: 550 | P57: 4.96 | Q57: 2400 | R57: =+ROUND(IF(P57>10,Q57/10*P57,Q57),0) -> 2400 | T57: =+R57+S57 -> 2400 | AA57: =+SUM(Table1[[#This Row],[DIESEL]:[FIXED EXP]]) -> 0 | AB57: =+Table1[[#This Row],[TOTAL AMOUNT]]-Table1[[#This Row],[TOTAL COST]] -> 2400
A58: 56 | B58: 46168 | C58: =SUBTOTAL(3,D$3:D58) -> 56 | D58: 46168 | H58: CHAKAN | I58: MTC TALAWADE | O58: 560 | P58: 4.54 | Q58: 2400 | R58: =+ROUND(IF(P58>10,Q58/10*P58,Q58),0) -> 2400 | T58: =+R58+S58 -> 2400 | AA58: =+SUM(Table1[[#This Row],[DIESEL]:[FIXED EXP]]) -> 0 | AB58: =+Table1[[#This Row],[TOTAL AMOUNT]]-Table1[[#This Row],[TOTAL COST]] -> 2400
A59: 57 | B59: 46169 | C59: =SUBTOTAL(3,D$3:D59) -> 57 | D59: 46169 | H59: CHAKAN | I59: MTC TALAWADE | O59: 570 | P59: 4.89 | Q59: 3200 | R59: =+ROUND(IF(P59>10,Q59/10*P59,Q59),0) -> 3200 | T59: =+R59+S59 -> 3200 | AA59: =+SUM(Table1[[#This Row],[DIESEL]:[FIXED EXP]]) -> 0 | AB59: =+Table1[[#This Row],[TOTAL AMOUNT]]-Table1[[#This Row],[TOTAL COST]] -> 3200
A60: 58 | B60: 46170 | C60: =SUBTOTAL(3,D$3:D60) -> 58 | D60: 46170 | H60: CHAKAN | I60: MTC TALAWADE | O60: 580 | P60: 5.06 | Q60: 3200 | R60: =+ROUND(IF(P60>10,Q60/10*P60,Q60),0) -> 3200 | T60: =+R60+S60 -> 3200 | AA60: =+SUM(Table1[[#This Row],[DIESEL]:[FIXED EXP]]) -> 0 | AB60: =+Table1[[#This Row],[TOTAL AMOUNT]]-Table1[[#This Row],[TOTAL COST]] -> 3200
C61: =SUBTOTAL(3,D$3:D61) -> 58 | AA61: =+SUM(Table1[[#This Row],[DIESEL]:[FIXED EXP]]) -> 0 | AB61: =+Table1[[#This Row],[TOTAL AMOUNT]]-Table1[[#This Row],[TOTAL COST]] -> 0
C62: =SUBTOTAL(3,D$3:D62) -> 58 | AA62: =+SUM(Table1[[#This Row],[DIESEL]:[FIXED EXP]]) -> 0 | AB62: =+Table1[[#This Row],[TOTAL AMOUNT]]-Table1[[#This Row],[TOTAL COST]] -> 0
C63: =SUBTOTAL(3,D$3:D63) -> 58 | AA63: =+SUM(Table1[[#This Row],[DIESEL]:[FIXED EXP]]) -> 0 | AB63: =+Table1[[#This Row],[TOTAL AMOUNT]]-Table1[[#This Row],[TOTAL COST]] -> 0
C64: =SUBTOTAL(3,D$3:D64) -> 58 | AA64: =+SUM(Table1[[#This Row],[DIESEL]:[FIXED EXP]]) -> 0 | AB64: =+Table1[[#This Row],[TOTAL AMOUNT]]-Table1[[#This Row],[TOTAL COST]] -> 0
...

Sheet Bill to Invoice
B1: BILL TO INVOICE
B3: "SHRI" | J3: 2
B4: CHAKRADHAR SWAMI TRANSPORT
B5: Address :- "SARVDNYA" Niwas,H.No.273,Opp. Sai Puja Baug. Soc.
B6: Near Rupali Laundry, Dattawadi,Akurdi,Pune-411 035
B7: Akurdi,Pune-411 035
B9: MTSPL CHK
F10: Date: | G10: =+ANNEXURE!D3 -> 46113
B11: =+_xlfn.XLOOKUP(B9,'PARTY CREATION'!$B:$B,'PARTY CREATION'!$C:$C) -> #NAME?
F13: Invoice No: | G13: 1
B14: GSTIN:27ATFPD4609J1ZQ
B15: FREIGHT BILL | F15: PAN NO. ADUPN8512H
B16: PARTICULARS | F16: V.CODE | G16: 4501310765
C17: NO. | D17: FROM | E17: TO | F17: Rate | G17: Trip | H17: Amount
D20: TRANSPORTATION CHARGESH AS PER | H20: =+ANNEXURE!M64 -> 94750
G34: FREIGHT AMT | H34: =SUM(H19:H33) -> 94750
F36: SGST%
F38: CGST%
F40: IGST%
G45: Total | H45: =SUM(H34:H44) -> 94750
B46: Total Amt. In Words:- Fourty Thousand Only
B50: Receiver's Signature : | F50: For CHAKRADHAR SWAMI TRANSPORT

Sheet ANNEXURE
A2: BILL NO :- | D2: =+CONCATENATE(VLOOKUP($D$4,'PARTY CREATION'!$B$3:$I$1048576,3),"-",E2) -> CST/SBD-1 | E2: 1
A3: BILL DATE :- | D3: =+VLOOKUP(E2,FREIGHT!A:B,2,) -> 46113
A4: PARTY NAME:- | D4: =+VLOOKUP(E2,FREIGHT!$A:$U,7,) -> SBD CHK
A5: SR | C5: DATE | D5: FROM PARTY NAME | E5: FROM PLACE | F5: TO PARTY NAME | G5: TO PLACE | H5: PARTY BILL NO | I5: QTY | J5: BASIC FREIGHT | K5: ACTUAL FREIGHT | L5: DET | M5: TOTAL | N5: DET. REMARK | O5: VH NO
A6: 1 | B6: =MATCH($E$2,OFFSET(FREIGHT!$A$1,B5,0,1000,1),0)+B5 -> 3 | C6: =IFERROR(INDEX(FREIGHT!$D:$D,$B6),"") -> 46113 | D6: =IFERROR(INDEX(FREIGHT!$I:$I,$B6),"") -> MTC CHAKAN | E6: =IFERROR(INDEX(FREIGHT!$J:$J,$B6),"") -> CHK | F6: =IFERROR(INDEX(FREIGHT!$K:$K,$B6),"") -> KFIL | G6: =IFERROR(INDEX(FREIGHT!$L:$L,$B6),"") -> JEJURI | H6: =IFERROR(INDEX(FREIGHT!$O:$O,$B6),"") -> 10 | I6: =IFERROR(INDEX(FREIGHT!$P:$P,$B6),"") -> 25 | J6: =IFERROR(INDEX(FREIGHT!$Q:$Q,$B6),"") -> 6500 | K6: =IFERROR(INDEX(FREIGHT!$R:$R,$B6),"") -> 16250 | L6: =IFERROR(INDEX(FREIGHT!$S:$S,$B6),"") -> 4000 | M6: =IFERROR(INDEX(FREIGHT!$T:$T,$B6),"") -> 20250 | N6: =IFERROR(INDEX(FREIGHT!$U:$U,$B6),"") -> 0 | O6: =IFERROR(INDEX(FREIGHT!$E:$E,$B6),"") -> MH12NX9008 | T6: =+IF(S6/K6*R6<=S6/10,S6/10,ROUND(S6/K6*R6,0)) -> 0
A7: =SUBTOTAL(3,C$6:C7) -> 2 | B7: =MATCH($E$2,OFFSET(FREIGHT!$A$1,B6,0,1000,1),0)+B6 -> 4 | C7: =IFERROR(INDEX(FREIGHT!$D:$D,$B7),"") -> 46114 | D7: =IFERROR(INDEX(FREIGHT!$I:$I,$B7),"") -> MTC TALAWADE | E7: =IFERROR(INDEX(FREIGHT!$J:$J,$B7),"") -> TAL | F7: =IFERROR(INDEX(FREIGHT!$K:$K,$B7),"") -> KFIL | G7: =IFERROR(INDEX(FREIGHT!$L:$L,$B7),"") -> JEJURI | H7: =IFERROR(INDEX(FREIGHT!$O:$O,$B7),"") -> 20 | I7: =IFERROR(INDEX(FREIGHT!$P:$P,$B7),"") -> 25 | J7: =IFERROR(INDEX(FREIGHT!$Q:$Q,$B7),"") -> 6500 | K7: =IFERROR(INDEX(FREIGHT!$R:$R,$B7),"") -> 16250 | L7: =IFERROR(INDEX(FREIGHT!$S:$S,$B7),"") -> 2000 | M7: =IFERROR(INDEX(FREIGHT!$T:$T,$B7),"") -> 18250 | N7: =IFERROR(INDEX(FREIGHT!$U:$U,$B7)," ") -> 0 | O7: =IFERROR(INDEX(FREIGHT!$E:$E,$B7),"") -> MH14KA2022
A8: =SUBTOTAL(3,C$6:C8) -> 3 | B8: =MATCH($E$2,OFFSET(FREIGHT!$A$1,B7,0,1000,1),0)+B7 -> 5 | C8: =IFERROR(INDEX(FREIGHT!$D:$D,$B8),"") -> 46115 | D8: =IFERROR(INDEX(FREIGHT!$I:$I,$B8),"") -> MTC TALAWADE | E8: =IFERROR(INDEX(FREIGHT!$J:$J,$B8),"") -> TAL | F8: =IFERROR(INDEX(FREIGHT!$K:$K,$B8),"") -> KFIL | G8: =IFERROR(INDEX(FREIGHT!$L:$L,$B8),"") -> JEJURI | H8: =IFERROR(INDEX(FREIGHT!$O:$O,$B8),"") -> 30 | I8: =IFERROR(INDEX(FREIGHT!$P:$P,$B8),"") -> 25 | J8: =IFERROR(INDEX(FREIGHT!$Q:$Q,$B8),"") -> 6500 | K8: =IFERROR(INDEX(FREIGHT!$R:$R,$B8),"") -> 16250 | L8: =IFERROR(INDEX(FREIGHT!$S:$S,$B8),"") -> 1000 | M8: =IFERROR(INDEX(FREIGHT!$T:$T,$B8),"") -> 17250 | N8: =IFERROR(INDEX(FREIGHT!$U:$U,$B8),"") -> 0 | O8: =IFERROR(INDEX(FREIGHT!$E:$E,$B8),"") -> MH12LT4896
A9: =SUBTOTAL(3,C$6:C9) -> 4 | B9: =MATCH($E$2,OFFSET(FREIGHT!$A$1,B8,0,1000,1),0)+B8 -> 6 | C9: =IFERROR(INDEX(FREIGHT!$D:$D,$B9),"") -> 46116 | D9: =IFERROR(INDEX(FREIGHT!$I:$I,$B9),"") -> MTC TALAWADE | E9: =IFERROR(INDEX(FREIGHT!$J:$J,$B9),"") -> TAL | F9: =IFERROR(INDEX(FREIGHT!$K:$K,$B9),"") -> KFIL | G9: =IFERROR(INDEX(FREIGHT!$L:$L,$B9),"") -> JEJURI | H9: =IFERROR(INDEX(FREIGHT!$O:$O,$B9),"") -> 40 | I9: =IFERROR(INDEX(FREIGHT!$P:$P,$B9),"") -> 25 | J9: =IFERROR(INDEX(FREIGHT!$Q:$Q,$B9),"") -> 7000 | K9: =IFERROR(INDEX(FREIGHT!$R:$R,$B9),"") -> 17500 | L9: =IFERROR(INDEX(FREIGHT!$S:$S,$B9),"") -> 0 | M9: =IFERROR(INDEX(FREIGHT!$T:$T,$B9),"") -> 17500 | N9: =IFERROR(INDEX(FREIGHT!$U:$U,$B9),"") -> 0 | O9: =IFERROR(INDEX(FREIGHT!$E:$E,$B9),"") -> MH12KP5927
A10: =SUBTOTAL(3,C$6:C10) -> 5 | B10: =MATCH($E$2,OFFSET(FREIGHT!$A$1,B9,0,1000,1),0)+B9 -> 7 | C10: =IFERROR(INDEX(FREIGHT!$D:$D,$B10),"") -> 46117 | D10: =IFERROR(INDEX(FREIGHT!$I:$I,$B10),"") -> MTC TALAWADE | E10: =IFERROR(INDEX(FREIGHT!$J:$J,$B10),"") -> CHK | F10: =IFERROR(INDEX(FREIGHT!$K:$K,$B10),"") -> KFIL | G10: =IFERROR(INDEX(FREIGHT!$L:$L,$B10),"") -> JEJURI | H10: =IFERROR(INDEX(FREIGHT!$O:$O,$B10),"") -> 50 | I10: =IFERROR(INDEX(FREIGHT!$P:$P,$B10),"") -> 25 | J10: =IFERROR(INDEX(FREIGHT!$Q:$Q,$B10),"") -> 7000 | K10: =IFERROR(INDEX(FREIGHT!$R:$R,$B10),"") -> 17500 | L10: =IFERROR(INDEX(FREIGHT!$S:$S,$B10),"") -> 0 | M10: =IFERROR(INDEX(FREIGHT!$T:$T,$B10),"") -> 17500 | N10: =IFERROR(INDEX(FREIGHT!$U:$U,$B10),"") -> 0 | O10: =IFERROR(INDEX(FREIGHT!$E:$E,$B10),"") -> MH12LT5574
A11: =SUBTOTAL(3,C$6:C11) -> 6 | B11: =MATCH($E$2,OFFSET(FREIGHT!$A$1,B10,0,1000,1),0)+B10 -> #N/A | C11: 46116 | D11: DETENTION | E11: CHK | F11: KFIL | G11: =IFERROR(INDEX(FREIGHT!$L:$L,$B11),"") | H11: 50 | I11: 25.15 | J11: 7000 | K11: =IFERROR(INDEX(FREIGHT!$R:$R,$B11),"") | L11: =IFERROR(INDEX(FREIGHT!$S:$S,$B11),"") | M11: 4000 | N11: =IFERROR(INDEX(FREIGHT!$U:$U,$B11),"") | O11: MH14KA2022
A12: =SUBTOTAL(3,C$6:C12) -> 7 | B12: =MATCH($E$2,OFFSET(FREIGHT!$A$1,B11,0,1000,1),0)+B11 -> #N/A | C12: =IFERROR(INDEX(FREIGHT!$D:$D,$B12),"") | D12: =IFERROR(INDEX(FREIGHT!$I:$I,$B12),"") | E12: =IFERROR(INDEX(FREIGHT!$J:$J,$B12),"") | F12: =IFERROR(INDEX(FREIGHT!$K:$K,$B12),"") | G12: =IFERROR(INDEX(FREIGHT!$L:$L,$B12),"") | H12: =IFERROR(INDEX(FREIGHT!$O:$O,$B12),"") | I12: =IFERROR(INDEX(FREIGHT!$P:$P,$B12),"") | J12: =IFERROR(INDEX(FREIGHT!$Q:$Q,$B12),"") | K12: =IFERROR(INDEX(FREIGHT!$R:$R,$B12),"") | L12: =IFERROR(INDEX(FREIGHT!$S:$S,$B12),"") | M12: =IFERROR(INDEX(FREIGHT!$T:$T,$B12),"") | N12: =IFERROR(INDEX(FREIGHT!$U:$U,$B12),"") | O12: =IFERROR(INDEX(FREIGHT!$E:$E,$B12),"")
A13: =SUBTOTAL(3,C$6:C13) -> 8 | B13: =MATCH($E$2,OFFSET(FREIGHT!$A$1,B12,0,1000,1),0)+B12 -> #N/A | C13: =IFERROR(INDEX(FREIGHT!$D:$D,$B13),"") | D13: =IFERROR(INDEX(FREIGHT!$I:$I,$B13),"") | E13: =IFERROR(INDEX(FREIGHT!$J:$J,$B13),"") | F13: =IFERROR(INDEX(FREIGHT!$K:$K,$B13),"") | G13: =IFERROR(INDEX(FREIGHT!$L:$L,$B13),"") | H13: =IFERROR(INDEX(FREIGHT!$O:$O,$B13),"") | I13: =IFERROR(INDEX(FREIGHT!$P:$P,$B13),"") | J13: =IFERROR(INDEX(FREIGHT!$Q:$Q,$B13),"") | K13: =IFERROR(INDEX(FREIGHT!$R:$R,$B13),"") | L13: =IFERROR(INDEX(FREIGHT!$S:$S,$B13),"") | M13: =IFERROR(INDEX(FREIGHT!$T:$T,$B13),"") | N13: =IFERROR(INDEX(FREIGHT!$U:$U,$B13),"") | O13: =IFERROR(INDEX(FREIGHT!$E:$E,$B13),"")
A14: =SUBTOTAL(3,C$6:C14) -> 9 | B14: =MATCH($E$2,OFFSET(FREIGHT!$A$1,B13,0,1000,1),0)+B13 -> #N/A | C14: =IFERROR(INDEX(FREIGHT!$D:$D,$B14),"") | D14: =IFERROR(INDEX(FREIGHT!$I:$I,$B14),"") | E14: =IFERROR(INDEX(FREIGHT!$J:$J,$B14),"") | F14: =IFERROR(INDEX(FREIGHT!$K:$K,$B14),"") | G14: =IFERROR(INDEX(FREIGHT!$L:$L,$B14),"") | H14: =IFERROR(INDEX(FREIGHT!$O:$O,$B14),"") | I14: =IFERROR(INDEX(FREIGHT!$P:$P,$B14),"") | J14: =IFERROR(INDEX(FREIGHT!$Q:$Q,$B14),"") | K14: =IFERROR(INDEX(FREIGHT!$R:$R,$B14),"") | L14: =IFERROR(INDEX(FREIGHT!$S:$S,$B14),"") | M14: =IFERROR(INDEX(FREIGHT!$T:$T,$B14),"") | N14: =IFERROR(INDEX(FREIGHT!$U:$U,$B14),"") | O14: =IFERROR(INDEX(FREIGHT!$E:$E,$B14),"")
A15: =SUBTOTAL(3,C$6:C15) -> 10 | B15: =MATCH($E$2,OFFSET(FREIGHT!$A$1,B14,0,1000,1),0)+B14 -> #N/A | C15: =IFERROR(INDEX(FREIGHT!$D:$D,$B15),"") | D15: =IFERROR(INDEX(FREIGHT!$I:$I,$B15),"") | E15: =IFERROR(INDEX(FREIGHT!$J:$J,$B15),"") | F15: =IFERROR(INDEX(FREIGHT!$K:$K,$B15),"") | G15: =IFERROR(INDEX(FREIGHT!$L:$L,$B15),"") | H15: =IFERROR(INDEX(FREIGHT!$O:$O,$B15),"") | I15: =IFERROR(INDEX(FREIGHT!$P:$P,$B15),"") | J15: =IFERROR(INDEX(FREIGHT!$Q:$Q,$B15),"") | K15: =IFERROR(INDEX(FREIGHT!$R:$R,$B15),"") | L15: =IFERROR(INDEX(FREIGHT!$S:$S,$B15),"") | M15: =IFERROR(INDEX(FREIGHT!$T:$T,$B15),"") | N15: =IFERROR(INDEX(FREIGHT!$U:$U,$B15),"") | O15: =IFERROR(INDEX(FREIGHT!$E:$E,$B15),"")
A16: =SUBTOTAL(3,C$6:C16) -> 11 | B16: =MATCH($E$2,OFFSET(FREIGHT!$A$1,B15,0,1000,1),0)+B15 -> #N/A | C16: =IFERROR(INDEX(FREIGHT!$D:$D,$B16),"") | D16: =IFERROR(INDEX(FREIGHT!$I:$I,$B16),"") | E16: =IFERROR(INDEX(FREIGHT!$J:$J,$B16),"") | F16: =IFERROR(INDEX(FREIGHT!$K:$K,$B16),"") | G16: =IFERROR(INDEX(FREIGHT!$L:$L,$B16),"") | H16: =IFERROR(INDEX(FREIGHT!$O:$O,$B16),"") | I16: =IFERROR(INDEX(FREIGHT!$P:$P,$B16),"") | J16: =IFERROR(INDEX(FREIGHT!$Q:$Q,$B16),"") | K16: =IFERROR(INDEX(FREIGHT!$R:$R,$B16),"") | L16: =IFERROR(INDEX(FREIGHT!$S:$S,$B16),"") | M16: =IFERROR(INDEX(FREIGHT!$T:$T,$B16),"") | N16: =IFERROR(INDEX(FREIGHT!$U:$U,$B16),"") | O16: =IFERROR(INDEX(FREIGHT!$E:$E,$B16),"")
A17: =SUBTOTAL(3,C$6:C17) -> 12 | B17: =MATCH($E$2,OFFSET(FREIGHT!$A$1,B16,0,1000,1),0)+B16 -> #N/A | C17: =IFERROR(INDEX(FREIGHT!$D:$D,$B17),"") | D17: =IFERROR(INDEX(FREIGHT!$I:$I,$B17),"") | E17: =IFERROR(INDEX(FREIGHT!$J:$J,$B17),"") | F17: =IFERROR(INDEX(FREIGHT!$K:$K,$B17),"") | G17: =IFERROR(INDEX(FREIGHT!$L:$L,$B17),"") | H17: =IFERROR(INDEX(FREIGHT!$O:$O,$B17),"") | I17: =IFERROR(INDEX(FREIGHT!$P:$P,$B17),"") | J17: =IFERROR(INDEX(FREIGHT!$Q:$Q,$B17),"") | K17: =IFERROR(INDEX(FREIGHT!$R:$R,$B17),"") | L17: =IFERROR(INDEX(FREIGHT!$S:$S,$B17),"") | M17: =IFERROR(INDEX(FREIGHT!$T:$T,$B17),"") | N17: =IFERROR(INDEX(FREIGHT!$U:$U,$B17),"") | O17: =IFERROR(INDEX(FREIGHT!$E:$E,$B17),"")
A18: =SUBTOTAL(3,C$6:C18) -> 13 | B18: =MATCH($E$2,OFFSET(FREIGHT!$A$1,B17,0,1000,1),0)+B17 -> #N/A | C18: =IFERROR(INDEX(FREIGHT!$D:$D,$B18),"") | D18: =IFERROR(INDEX(FREIGHT!$I:$I,$B18),"") | E18: =IFERROR(INDEX(FREIGHT!$J:$J,$B18),"") | F18: =IFERROR(INDEX(FREIGHT!$K:$K,$B18),"") | G18: =IFERROR(INDEX(FREIGHT!$L:$L,$B18),"") | H18: =IFERROR(INDEX(FREIGHT!$O:$O,$B18),"") | I18: =IFERROR(INDEX(FREIGHT!$P:$P,$B18),"") | J18: =IFERROR(INDEX(FREIGHT!$Q:$Q,$B18),"") | K18: =IFERROR(INDEX(FREIGHT!$R:$R,$B18),"") | L18: =IFERROR(INDEX(FREIGHT!$S:$S,$B18),"") | M18: =IFERROR(INDEX(FREIGHT!$T:$T,$B18),"") | N18: =IFERROR(INDEX(FREIGHT!$U:$U,$B18),"") | O18: =IFERROR(INDEX(FREIGHT!$E:$E,$B18),"")
A19: =SUBTOTAL(3,C$6:C19) -> 14 | B19: =MATCH($E$2,OFFSET(FREIGHT!$A$1,B18,0,1000,1),0)+B18 -> #N/A | C19: =IFERROR(INDEX(FREIGHT!$D:$D,$B19),"") | D19: =IFERROR(INDEX(FREIGHT!$I:$I,$B19),"") | E19: =IFERROR(INDEX(FREIGHT!$J:$J,$B19),"") | F19: =IFERROR(INDEX(FREIGHT!$K:$K,$B19),"") | G19: =IFERROR(INDEX(FREIGHT!$L:$L,$B19),"") | H19: =IFERROR(INDEX(FREIGHT!$O:$O,$B19),"") | I19: =IFERROR(INDEX(FREIGHT!$P:$P,$B19),"") | J19: =IFERROR(INDEX(FREIGHT!$Q:$Q,$B19),"") | K19: =IFERROR(INDEX(FREIGHT!$R:$R,$B19),"") | L19: =IFERROR(INDEX(FREIGHT!$S:$S,$B19),"") | M19: =IFERROR(INDEX(FREIGHT!$T:$T,$B19),"") | N19: =IFERROR(INDEX(FREIGHT!$U:$U,$B19),"") | O19: =IFERROR(INDEX(FREIGHT!$E:$E,$B19),"")
A20: =SUBTOTAL(3,C$6:C20) -> 15 | B20: =MATCH($E$2,OFFSET(FREIGHT!$A$1,B19,0,1000,1),0)+B19 -> #N/A | C20: =IFERROR(INDEX(FREIGHT!$D:$D,$B20),"") | D20: =IFERROR(INDEX(FREIGHT!$I:$I,$B20),"") | E20: =IFERROR(INDEX(FREIGHT!$J:$J,$B20),"") | F20: =IFERROR(INDEX(FREIGHT!$K:$K,$B20),"") | G20: =IFERROR(INDEX(FREIGHT!$L:$L,$B20),"") | H20: =IFERROR(INDEX(FREIGHT!$O:$O,$B20),"") | I20: =IFERROR(INDEX(FREIGHT!$P:$P,$B20),"") | J20: =IFERROR(INDEX(FREIGHT!$Q:$Q,$B20),"") | K20: =IFERROR(INDEX(FREIGHT!$R:$R,$B20),"") | L20: =IFERROR(INDEX(FREIGHT!$S:$S,$B20),"") | M20: =IFERROR(INDEX(FREIGHT!$T:$T,$B20),"") | N20: =IFERROR(INDEX(FREIGHT!$U:$U,$B20),"") | O20: =IFERROR(INDEX(FREIGHT!$E:$E,$B20),"")
A21: =SUBTOTAL(3,C$6:C21) -> 16 | B21: =MATCH($E$2,OFFSET(FREIGHT!$A$1,B20,0,1000,1),0)+B20 -> #N/A | C21: =IFERROR(INDEX(FREIGHT!$D:$D,$B21),"") | D21: =IFERROR(INDEX(FREIGHT!$I:$I,$B21),"") | E21: =IFERROR(INDEX(FREIGHT!$J:$J,$B21),"") | F21: =IFERROR(INDEX(FREIGHT!$K:$K,$B21),"") | G21: =IFERROR(INDEX(FREIGHT!$L:$L,$B21),"") | H21: =IFERROR(INDEX(FREIGHT!$O:$O,$B21),"") | I21: =IFERROR(INDEX(FREIGHT!$P:$P,$B21),"") | J21: =IFERROR(INDEX(FREIGHT!$Q:$Q,$B21),"") | K21: =IFERROR(INDEX(FREIGHT!$R:$R,$B21),"") | L21: =IFERROR(INDEX(FREIGHT!$S:$S,$B21),"") | M21: =IFERROR(INDEX(FREIGHT!$T:$T,$B21),"") | N21: =IFERROR(INDEX(FREIGHT!$U:$U,$B21),"") | O21: =IFERROR(INDEX(FREIGHT!$E:$E,$B21),"")
A22: =SUBTOTAL(3,C$6:C22) -> 17 | B22: =MATCH($E$2,OFFSET(FREIGHT!$A$1,B21,0,1000,1),0)+B21 -> #N/A | C22: =IFERROR(INDEX(FREIGHT!$D:$D,$B22),"") | D22: =IFERROR(INDEX(FREIGHT!$I:$I,$B22),"") | E22: =IFERROR(INDEX(FREIGHT!$J:$J,$B22),"") | F22: =IFERROR(INDEX(FREIGHT!$K:$K,$B22),"") | G22: =IFERROR(INDEX(FREIGHT!$L:$L,$B22),"") | H22: =IFERROR(INDEX(FREIGHT!$O:$O,$B22),"") | I22: =IFERROR(INDEX(FREIGHT!$P:$P,$B22),"") | J22: =IFERROR(INDEX(FREIGHT!$Q:$Q,$B22),"") | K22: =IFERROR(INDEX(FREIGHT!$R:$R,$B22),"") | L22: =IFERROR(INDEX(FREIGHT!$S:$S,$B22),"") | M22: =IFERROR(INDEX(FREIGHT!$T:$T,$B22),"") | N22: =IFERROR(INDEX(FREIGHT!$U:$U,$B22),"") | O22: =IFERROR(INDEX(FREIGHT!$E:$E,$B22),"")
A23: =SUBTOTAL(3,C$6:C23) -> 18 | B23: =MATCH($E$2,OFFSET(FREIGHT!$A$1,B22,0,1000,1),0)+B22 -> #N/A | C23: =IFERROR(INDEX(FREIGHT!$D:$D,$B23),"") | D23: =IFERROR(INDEX(FREIGHT!$I:$I,$B23),"") | E23: =IFERROR(INDEX(FREIGHT!$J:$J,$B23),"") | F23: =IFERROR(INDEX(FREIGHT!$K:$K,$B23),"") | G23: =IFERROR(INDEX(FREIGHT!$L:$L,$B23),"") | H23: =IFERROR(INDEX(FREIGHT!$O:$O,$B23),"") | I23: =IFERROR(INDEX(FREIGHT!$P:$P,$B23),"") | J23: =IFERROR(INDEX(FREIGHT!$Q:$Q,$B23),"") | K23: =IFERROR(INDEX(FREIGHT!$R:$R,$B23),"") | L23: =IFERROR(INDEX(FREIGHT!$S:$S,$B23),"") | M23: =IFERROR(INDEX(FREIGHT!$T:$T,$B23),"") | N23: =IFERROR(INDEX(FREIGHT!$U:$U,$B23),"") | O23: =IFERROR(INDEX(FREIGHT!$E:$E,$B23),"")
... A63: =SUBTOTAL(3,C$6:C63) -> 58 | B63: =MATCH($E$2,OFFSET(FREIGHT!$A$1,B62,0,1000,1),0)+B62 -> #N/A | C63: =IFERROR(INDEX(FREIGHT!$D:$D,$B63),"") | D63: =IFERROR(INDEX(FREIGHT!$I:$I,$B63),"") | E63: =IFERROR(INDEX(FREIGHT!$J:$J,$B63),"") | F63: =IFERROR(INDEX(FREIGHT!$K:$K,$B63),"") | G63: =IFERROR(INDEX(FREIGHT!$L:$L,$B63),"") | H63: =IFERROR(INDEX(FREIGHT!$O:$O,$B63),"") | I63: =IFERROR(INDEX(FREIGHT!$P:$P,$B63),"") | J63: =IFERROR(INDEX(FREIGHT!$Q:$Q,$B63),"") | K63: =IFERROR(INDEX(FREIGHT!$R:$R,$B63),"") | L63: =IFERROR(INDEX(FREIGHT!$S:$S,$B63),"") | M63: =IFERROR(INDEX(FREIGHT!$T:$T,$B63),"") | N63: =IFERROR(INDEX(FREIGHT!$U:$U,$B63),"") | O63: =IFERROR(INDEX(FREIGHT!$E:$E,$B63),"")
K64: =SUM(K6:K63) -> 83750 | L64: =SUM(L6:L63) -> 7000 | M64: =SUM(M6:M63) -> 94750

Sheet PARTY CREATION
A2: SR NO | B2: BILLING PARTY NAME | C2: ADDRESS | D2: BILLING CODE | E2: VENDOR CODE | F2: GSTIN
A3: 1 | B3: MTC CHK | C3: CHAKAN | D3: CST/MTC | E3: 123
A4: 2 | B4: MTC TAL | C4: TALAWADE | D4: CST/MTC | E4: 123
A5: 3 | B5: SBA METAL | C5: CHAKAN | D5: SBA/MTSPL | E5: 789
A6: 4 | B6: MTC MUM | C6: MUMBAI | D6: CST/MTC | E6: 456
A7: 5 | B7: SBD CHK | C7: CHAKAN | D7: CST/SBD | E7: 555
A8: 6
A9: 7
A10: 8
A11: 9

Sheet EXPENSES
A2: SR NO | B2: DATE | C2: TYPE | D2: CLASS | E2: VH NO | F2: DRIVER | G2: DISCRIPTION | H2: PLACE | I2: AMOUNT
A4: =SUBTOTAL(3,B$4:B4) -> 1 | B4: 46113 | C4: EXP | D4: MAINTENANCE | F4: VIJAY | G4: CLUCH REPAIR | I4: 5000
A5: =SUBTOTAL(3,B$4:B5) -> 2 | B5: 46114 | C5: EXP | D5: DRV ADVANCE | F5: ASHOK | G5: ADVANCE | I5: 2000
A6: =SUBTOTAL(3,B$4:B6) -> 3 | B6: 46115 | C6: EXP | D6: MAINTENANCE | F6: RAHUL | G6: PUNCHER | I6: 3000
A7: =SUBTOTAL(3,B$4:B7) -> 3
A8: =SUBTOTAL(3,B$4:B8) -> 3
A9: =SUBTOTAL(3,B$4:B9) -> 3
A10: =SUBTOTAL(3,B$4:B10) -> 3
A11: =SUBTOTAL(3,B$4:B11) -> 3
A12: =SUBTOTAL(3,B$4:B12) -> 3
A13: =SUBTOTAL(3,B$4:B13) -> 3
A14: =SUBTOTAL(3,B$4:B14) -> 3
A15: =SUBTOTAL(3,B$4:B15) -> 3
A16: =SUBTOTAL(3,B$4:B16) -> 3
A17: =SUBTOTAL(3,B$4:B17) -> 3
A18: =SUBTOTAL(3,B$4:B18) -> 3
... A31: =SUBTOTAL(3,B$4:B31) -> 3
